Using TensorFlow backend.
/home/groups/dlmrimnd/jacob/miniconda3/envs/segisnet_env/lib/python3.6/importlib/_bootstrap.py:219: RuntimeWarning: compiletime version 3.5 of module 'tensorflow.python.framework.fast_tensor_util' does not match runtime version 3.6
  return f(*args, **kwds)
Traceback (most recent call last):
  File "/home/groups/dlmrimnd/jacob/projects/Segis-Net/code/Segis-Net/Train_SegisNet.py", line 149, in <module>
    indexing='ij',alpha=a)
  File "/home/groups/dlmrimnd/jacob/projects/Segis-Net/code/Segis-Net/SegisNet_model_dataGenerator.py", line 105, in joint_model
    src_segm = seg_model(S_src)
  File "/home/groups/dlmrimnd/jacob/miniconda3/envs/segisnet_env/lib/python3.6/site-packages/keras/engine/base_layer.py", line 460, in __call__
    output = self.call(inputs, **kwargs)
  File "/home/groups/dlmrimnd/jacob/miniconda3/envs/segisnet_env/lib/python3.6/site-packages/keras/engine/network.py", line 573, in call
    output_tensors, _, _ = self.run_internal_graph(inputs, masks)
  File "/home/groups/dlmrimnd/jacob/miniconda3/envs/segisnet_env/lib/python3.6/site-packages/keras/engine/network.py", line 730, in run_internal_graph
    output_tensors = to_list(layer.call(computed_tensor, **kwargs))
  File "/home/groups/dlmrimnd/jacob/miniconda3/envs/segisnet_env/lib/python3.6/site-packages/keras/layers/convolutional.py", line 176, in call
    dilation_rate=self.dilation_rate)
  File "/home/groups/dlmrimnd/jacob/miniconda3/envs/segisnet_env/lib/python3.6/site-packages/keras/backend/tensorflow_backend.py", line 3805, in conv3d
    data_format=tf_data_format)
  File "/home/groups/dlmrimnd/jacob/miniconda3/envs/segisnet_env/lib/python3.6/site-packages/tensorflow/python/ops/nn_ops.py", line 750, in convolution
    name=name, data_format=data_format)
  File "/home/groups/dlmrimnd/jacob/miniconda3/envs/segisnet_env/lib/python3.6/site-packages/tensorflow/python/ops/nn_ops.py", line 796, in __init__
    input_channels_dim = input_shape[num_spatial_dims + 1]
  File "/home/groups/dlmrimnd/jacob/miniconda3/envs/segisnet_env/lib/python3.6/site-packages/tensorflow/python/framework/tensor_shape.py", line 521, in __getitem__
    return self._dims[key]
IndexError: list index out of range
